{"errorMessage": "An error occurred (404) when calling the HeadObject operation: Not Found", "errorType": "ClientError", "requestId": "37dbb636-4d50-4b6e-bd47-20f3e1dbdb64", "stackTrace": ["  File \"/var/task/index.py\", line 18, in lambda_handler\n    response = s3_client.head_object(Bucket=bucket, Key=key)\n", "  File \"/var/runtime/botocore/client.py\", line 565, in _api_call\n    return self._make_api_call(operation_name, kwargs)\n", "  File \"/var/runtime/botocore/client.py\", line 1021, in _make_api_call\n    raise error_class(parsed_response, operation_name)\n"]}